<?xml version="1.0"?>
<robot name="myrobot">

    <material name="blue">
      <color rgba="0 0 0.8 1"/>
    </material>

    <material name="white">
      <color rgba="1 1 1 1"/>
    </material>

    <link name="dummy">
      </link>
  
    <joint name="dummy_joint" type="fixed">
      <parent link="dummy"/>
      <child link="chasis"/>
    </joint>


  <link name="chasis">
    <visual>
      <geometry>
        <box size="0.05 0.45 0.05" />
      </geometry>
      <origin rpy="0 0 0" xyz="0 0 0"/>
      <material name="white"/>
    </visual>

    <collision>
      <geometry>
        <box size="0.05 0.45 0.05" />
      </geometry>
      <origin rpy="0 0 0" xyz="0 0 0"/>
    </collision>

    <inertial>
      <mass value="1"/>
      <origin xyz="0 0 0" rpy="0 0 0"/>
      <inertia ixx="0.1126" ixy="0.0" ixz="0.0" iyy="0.1126" iyz="0.0" izz="0.2345"/>
    </inertial>
  </link>


  <gazebo reference="chasis">
    <material>Gazebo/Orange</material>
  </gazebo>

  <gazebo reference="pendulum">
    <material>Gazebo/Blue</material>
  </gazebo>

  <gazebo reference="left_wheel">
    <material>Gazebo/White</material>
  </gazebo>

  <gazebo reference="right_wheel">
    <material>Gazebo/White</material>
  </gazebo>

  <link name="pendulum">
    <visual>
      <geometry>
        <box size="0.05 0.05 0.8"/>
      </geometry>
      <origin rpy="0 0 0" xyz="0 0 0.4"/>
      <material name="blue"/>
    </visual>

    <collision>
      <geometry>
        <box size="0.05 0.05 0.8"/>
      </geometry>
      <origin rpy="0 0 0" xyz="0 0 0.4"/>
    </collision>

    <inertial>
      <mass value="14"/>
      <origin xyz="0 0 0.4035" rpy="0 0 0"/>
      <inertia ixx="0.1" ixy="0.0" ixz="0.0" iyy="1.4" iyz="0.0" izz="0.2345"/>
    </inertial>
  </link>


  <joint name="chasis_to_pendulum" type="fixed">
    <parent link="chasis"/>
    <child link="pendulum"/>
    <origin xyz="0 0 0.025"/>
  </joint>

  <link name="left_wheel">
    <visual>
      <geometry>
        <cylinder length="0.05" radius="0.1"/>
      </geometry>
      <origin rpy="1.57075 0 0" xyz="0 0 0"/>
      <material name="white"/>
    </visual>

    <collision>
      <geometry>
        <cylinder length="0.05" radius="0.1"/>
      </geometry>
      <origin rpy="1.57075 0 0" xyz="0 0 0"/> 
    </collision>

    <inertial>
      <mass value="4"/>
      <origin xyz="0 0 0" rpy="1.57075 0 0"/>
      <inertia ixx="0.01" ixy="0.0" ixz="0.0" iyy="0.021" iyz="0.0" izz="0.01"/>
    </inertial>
  </link>

  <joint name="chasis_to_left_wheel" type="continuous">
    <parent link="chasis"/>
    <child link="left_wheel"/>
    <axis xyz="0 1 0"/>
    <origin xyz="0 0.25 0"/>
    <limit effort="100" velocity="1000.0"/>
  </joint>

  <link name="right_wheel">
    <visual>
      <geometry>
        <cylinder length="0.05" radius="0.1"/>
      </geometry>
      <origin rpy="1.57075 0 0" xyz="0 0 0"/>
      <material name="white"/>
    </visual>

    <collision>
      <geometry>
        <cylinder length="0.05" radius="0.1"/>
      </geometry>
      <origin rpy="1.57075 0 0" xyz="0 0 0"/>
    </collision>

    <inertial>
      <mass value="4"/>
      <origin xyz="0 0 0" rpy="1.57075 0 0"/>
      <inertia ixx="0.01" ixy="0.0" ixz="0.0" iyy="0.021" iyz="0.0" izz="0.01"/>
    </inertial>
  </link>


  <joint name="chasis_to_right_wheel" type="continuous">
    <parent link="chasis"/>
    <child link="right_wheel"/>
    <axis xyz="0 1 0"/>
    <origin xyz="0 -0.25 0"/>
    <limit effort="100" velocity="1000.0"/>
  </joint>


  <gazebo>
    <plugin name="gazebo_ros_control" filename="libgazebo_ros_control.so">
    <robotNamespace>/myrobot</robotNamespace>
    </plugin>
  </gazebo>

  <transmission name="tran1">
    <type>transmission_interface/SimpleTransmission</type>
    <joint name="chasis_to_left_wheel">
      <hardwareInterface>EffortJointInterface</hardwareInterface>
    </joint>
    <actuator name="left_motor">
      <hardwareInterface>EffortJointInterface</hardwareInterface>
      <mechanicalReduction>1</mechanicalReduction>
    </actuator>
  </transmission>

  <transmission name="tran2">
    <type>transmission_interface/SimpleTransmission</type>
    <joint name="chasis_to_right_wheel">
      <hardwareInterface>EffortJointInterface</hardwareInterface>
    </joint>
    <actuator name="right_motor">
      <hardwareInterface>EffortJointInterface</hardwareInterface>
      <mechanicalReduction>1</mechanicalReduction>
    </actuator>
  </transmission>

  <gazebo>
    <plugin name="p3d_base_controller" filename="libgazebo_ros_p3d.so">
      <alwaysOn>true</alwaysOn>
      <updateRate>350.0</updateRate>
      <bodyName>chasis</bodyName>
      <topicName>ground_truth/state</topicName>
      <gaussianNoise>0.0</gaussianNoise>
      <frameName>world</frameName>
      <xyzOffsets>0 0 0</xyzOffsets>
      <rpyOffsets>0 0 0</rpyOffsets>
    </plugin>
  </gazebo>

  <joint name="imu_joint" type="fixed">
    <axis xyz="1 0 0"/> <!-- 0 1 0 -->
    <origin xyz="0 0 0"/>
    <parent link="chasis"/>
    <child link="imu_link"/>
  </joint>


<link name="imu_link">
  <inertial>
    <mass value="0.001"/>
    <origin rpy="0 0 0" xyz="0 0 0"/>
    <inertia ixx="0.0001" ixy="0" ixz="0" iyy="0.000001" iyz="0" izz="0.0001"/>
  </inertial>
  <visual>
    <origin rpy="0 0 0" xyz="0 0 0"/>
    <geometry>
      <box size="0.001 0.001 0.001"/>
    </geometry>
  </visual>
  <collision>
    <origin rpy="0 0 0" xyz="0 0 0"/>
    <geometry>
      <box size=".001 .001 .001"/>
    </geometry>
  </collision>
</link>

  <gazebo reference="imu_link">
    <gravity>true</gravity>
    <sensor name="imu_sensor" type="imu">
      <always_on>true</always_on>
      <update_rate>350.0</update_rate>
      <visualize>true</visualize>
      <topic>__default_topic__</topic>
      <plugin filename="libgazebo_ros_imu_sensor.so" name="imu_plugin">
        <topicName>imu</topicName>
        <bodyName>imu_link</bodyName>
        <updateRateHZ>350.0</updateRateHZ>
        <gaussianNoise>0.0</gaussianNoise>
        <xyzOffset>0 0 0</xyzOffset>
        <rpyOffset>0 0 0</rpyOffset>
        <frameName>imu_link</frameName>
      </plugin>
      <pose>0 0 0 0 0 0</pose>
    </sensor>
  </gazebo>


</robot>
